Workbook
Name Absa__GH__LTD: 'Bank Data'!$C$3:$C$97
Name Access_Bank__Ghana__Plc: 'Bank Data'!$F$3:$F$55
Name Agricultural_Development_Bank_Limited: 'Bank Data'!$I$3:$I$94
Name Apex_Bank_GH_Limited: 'Bank Data'!$L$3:$L$164
Name Bank_of_Africa_Ghana_Limited: 'Bank Data'!$O$3:$O$31
Name Bank_of_Ghana: 'Bank Data'!$R$3:$R$12
Name BankBranchCode: 'Bank Data'!$CI$3:$CI$1508
Name BankBranchName: 'Bank Data'!$CH$3:$CH$1508
Name BankName: 'Bank Data'!$A$3:$A$30
Name BSIC_Ghana_Limited: 'Bank Data'!$U$3:$U$16
Name CAL_Bank_Limited: 'Bank Data'!$X$3:$X$42
Name Consolidated_Bank_Ghana_Limited: 'Bank Data'!$AA$3:$AA$119
Name Ecobank_Ghana_Limited: 'Bank Data'!$AD$3:$AD$91
Name FBN_Bank__Ghana__Limited: 'Bank Data'!$AG$3:$AG$22
Name Fidelity_Bank_Limited: 'Bank Data'!$AJ$3:$AJ$94
Name First_Atlantic_Bank_Limited: 'Bank Data'!$AM$3:$AM$38
Name First_National_Bank__Ghana__Limited: 'Bank Data'!$AP$3:$AP$11
Name GCB_Bank_Limited: 'Bank Data'!$AS$3:$AS$194
Name GHL_Bank_Limited: 'Bank Data'!$AV$3:$AV$6
Name GN_Bank_Limited: 'Bank Data'!#REF!
Name Guaranty_Trust_Bank__Ghana__Limited: 'Bank Data'!$AZ$3:$AZ$43
Name National_Investment_Bank_Limited: 'Bank Data'!$BC$3:$BC$70
Name Omni_Bank_Ghana_Limited: 'Bank Data'!$BF$3:$BF$28
Name Prudential_Bank_Limited: 'Bank Data'!$BI$3:$BI$43
Name Republic_Bank__Ghana__Limited: 'Bank Data'!$BL$3:$BL$50
Name Societe_General__Ghana__Limited: 'Bank Data'!$BO$3:$BO$52
Name Stanbic_Bank_Ghana_Limited: 'Bank Data'!$BR$3:$BR$49
Name Standard_Chartered_Bank__Ghana__Limited: 'Bank Data'!$BU$3:$BU$25
Name United_Bank_for_Africa__Ghana__Limited: 'Bank Data'!$BX$3:$BX$25
Name Universal_Merchant_Bank_Limited: 'Bank Data'!$CA$3:$CA$59
Name Zenith_Bank__Ghana__Limited: 'Bank Data'!$CD$3:$CD$30

Sheet employees
A1: Required Information | G1: Additional Information (Optional) | R1: Other Information
A2: FirstName | B2: LastName | C2: BasicSalary | D2: SocialSecurityNumber | E2: EmailAddress | F2: MobileNumber | G2: OtherNames | H2: EmployeeTrusteeId | I2: WorkerType | J2: PaymentDestination | K2: BankName | L2: BankBranchName | M2: BankBranchSortCode | N2: BankAccountName | O2: BankAccountNumber | P2: MomoNetwork | Q2: MomoAccountName | R2: MomoAccountNumber | S2: Gender | T2: MaritalStatus | U2: BirthDate | V2: Nationality | W2: NationalIdType | X2: NationalIdNumber | Y2: EmployeeNumber | Z2: EmployeeStatus | AA2: EmployeeStatusEndDate | AB2: HireDate | AC2: JobPosition | AD2: Department | AE2: Division | AF2: Unit | AG2: PayBand | AH2: Location | AI2: IncludeInPayroll | AJ2: PayType | AK2: Currency
A3: PEARL | B3: WEBU | C3: 3391.54 | D3: C19304210265 | E3: webupearl392@gmail.com | F3: 0544628316 | I3: EMPLOYEE | M3: =_xlfn.IFNA(VLOOKUP(_xlfn.CONCAT(K3,L3),'Bank Data'!$CH$3:$CI$1508,2,0),"") | S3: FEMALE | T3: MARRIED | V3: Ghana | W3: GHANA CARD | X3: GHA-712506684-9 | Y3: NKA209 | AB3: 01/11/2021 | AC3: CHECK IN OFFICER | AF3: AIRPORT | AH3: AIRPORT | AI3: YES | AJ3: SALARY | AK3: GHS
A4: GLORIA | B4: SEFAH SAAH | C4: 5239.05 | D4: J018110290025 | E4: kespong20156@gmail.com | F4: 0202735517 | I4: EMPLOYEE | M4: =_xlfn.IFNA(VLOOKUP(_xlfn.CONCAT(K4,L4),'Bank Data'!$CH$3:$CI$1508,2,0),"") | S4: FEMALE | T4: MARRIED | V4: Ghana | W4: GHANA CARD | X4: GHA-001364952-8 | Y4: NKA060 | AB4: 01/08/2007 | AC4: IMAGE ANALYST | AF4: AIRPORT | AH4: AIRPORT | AI4: YES | AJ4: SALARY | AK4: GHS
A5: KOFI | B5: NANA ADJEI | C5: 6715.48 | E5: nanakofiadjei1929@gmail.com | F5: 0505718804 | I5: EMPLOYEE | M5: =_xlfn.IFNA(VLOOKUP(_xlfn.CONCAT(K5,L5),'Bank Data'!$CH$3:$CI$1508,2,0),"") | S5: MALE | V5: Ghana | W5: GHANA CARD | X5: GHA-725971370-7 | Y5: NTE140 | AB5: 04/08/2015 | AC5: COODINATOR | AF5: TEMA MAIN | AH5: TEMA MAIN | AI5: YES | AJ5: SALARY | AK5: GHS
A6: OSMAN | B6: AWE ADDA | C6: 1463.09 | D6: J138001010039 | E6: aweoman8002@gmail.com | F6: 0543816312 | I6: EMPLOYEE | M6: =_xlfn.IFNA(VLOOKUP(_xlfn.CONCAT(K6,L6),'Bank Data'!$CH$3:$CI$1508,2,0),"") | S6: MALE | V6: Ghana | W6: GHANA CARD | X6: GHA-727455931-3 | Y6: NPA224 | AB6: 01/11/2021 | AC6: SECURITY | AF6: PAGA | AH6: PAGA | AI6: YES | AJ6: SALARY | AK6: GHS
A7: ALICE | B7: BAFFOE | C7: 3594.51 | D7: G097911120020 | E7: obaapayiwa@yahoo.com | F7: 0245697254 | I7: EMPLOYEE | M7: =_xlfn.IFNA(VLOOKUP(_xlfn.CONCAT(K7,L7),'Bank Data'!$CH$3:$CI$1508,2,0),"") | S7: FEMALE | V7: Ghana | W7: GHANA CARD | X7: GHA-713421810-1 | Y7: NKA118 | AB7: 02/01/2014 | AC7: CHECK IN OFFICER | AF7: AIRPORT | AH7: AIRPORT | AI7: YES | AJ7: SALARY | AK7: GHS
A8: AUGUSTINE | B8: EFFAH | C8: 3438.85 | D8: G098502250019 | E8: augustineeffah5@gmail.com | F8: 0242226571 | I8: EMPLOYEE | M8: =_xlfn.IFNA(VLOOKUP(_xlfn.CONCAT(K8,L8),'Bank Data'!$CH$3:$CI$1508,2,0),"") | S8: MALE | T8: MARRIED | V8: Ghana | W8: GHANA CARD | X8: GHA-001100473-2 | Y8: NTE156 | AB8: 01/02/2016 | AC8: DRIVER | AF8: TEMA MAIN | AH8: TEMA MAIN | AI8: YES | AJ8: SALARY | AK8: GHS
A9: JOANA | B9: BOAMPONG | C9: 4653 | D9: E018612210025 | E9: joanaboampong@yahoo.com | F9: 0246412874 | I9: EMPLOYEE | M9: =_xlfn.IFNA(VLOOKUP(_xlfn.CONCAT(K9,L9),'Bank Data'!$CH$3:$CI$1508,2,0),"") | S9: FEMALE | V9: Ghana | W9: GHANA CARD | X9: GHA-001282314-5 | Y9: NKA093 | AB9: 04/03/2013 | AC9: IMAGE ANALYST | AF9: AIRPORT | AH9: AIRPORT | AI9: YES | AJ9: SALARY | AK9: GHS
A10: JOY | B10: KAFUI KWAKUYI | C10: 3716.51 | D10: C019201140375 | E10: joy.kafui@yahoo.com | F10: 0269408482 | I10: EMPLOYEE | M10: =_xlfn.IFNA(VLOOKUP(_xlfn.CONCAT(K10,L10),'Bank Data'!$CH$3:$CI$1508,2,0),"") | S10: MALE | V10: Ghana | W10: GHANA CARD | X10: GHA-002422937-3 | Y10: NPA192 | AB10: 01/01/2018 | AC10: IMAGE ANALYST | AF10: PAGE | AH10: PAGE | AI10: YES | AJ10: SALARY | AK10: GHS
A11: BRIGHT | B11: MENKA ASARE | C11: 16546.48 | D11: G097806130011 | E11: bmasare@gmail.com | F11: 0244096691 | I11: EMPLOYEE | M11: =_xlfn.IFNA(VLOOKUP(_xlfn.CONCAT(K11,L11),'Bank Data'!$CH$3:$CI$1508,2,0),"") | S11: MALE | T11: MARRIED | V11: Ghana | W11: GHANA CARD | X11: GHA-713483593-1 | Y11: NTE008 | AB11: 01/03/2004 | AC11: MANAGER -TEMA | AF11: TEMA MAIN | AH11: TEMA MAIN | AI11: YES | AJ11: SALARY | AK11: GHS
A12: SADAT | B12: ADAM SINARE | C12: 9880.88 | D12: C018512190115 | E12: sinare19@yahoo.com | F12: 0244669561 | I12: EMPLOYEE | M12: =_xlfn.IFNA(VLOOKUP(_xlfn.CONCAT(K12,L12),'Bank Data'!$CH$3:$CI$1508,2,0),"") | S12: MALE | T12: MARRIED | V12: Ghana | W12: GHANA CARD | X12: GHA-727378066-4 | Y12: NTE012 | AB12: 01/08/2011 | AC12: ASSISTANT MANAGER SENTRY PORTAL | AF12: TEMA-SENTRY PORTAL | AH12: TEMA-SENTRY PORTAL | AI12: YES | AJ12: SALARY | AK12: GHS
A13: ALBERT | B13: SOWA BOYE | C13: 3350.51 | D13: C017208240479 | E13: bertocalus@gmail.com | F13: 0244816212 | I13: EMPLOYEE | M13: =_xlfn.IFNA(VLOOKUP(_xlfn.CONCAT(K13,L13),'Bank Data'!$CH$3:$CI$1508,2,0),"") | S13: MALE | T13: MARRIED | V13: Ghana | W13: GHANA CARD | X13: GHA-003697605-2 | Y13: NPA193 | AB13: 01/01/2018 | AC13: I.T OFFICER | AF13: PAGA | AH13: PAGA | AI13: YES | AJ13: SALARY | AK13: GHS
A14: PRINCE | B14: MARMAH | C14: 6882.35 | D14: F019004240053 | E14: marmahp@gmail.com | F14: 0242373473 | I14: EMPLOYEE | M14: =_xlfn.IFNA(VLOOKUP(_xlfn.CONCAT(K14,L14),'Bank Data'!$CH$3:$CI$1508,2,0),"") | S14: MALE | T14: MARRIED | V14: Ghana | W14: GHANA CARD | X14: GHA-727288015-0 | Y14: NKA112 | AB14: 02/09/2013 | AC14: ASSISTANT INFO TECH MANAGER | AF14: TEMA MAIN | AH14: TEMA MAIN | AI14: YES | AJ14: SALARY | AK14: GHS
A15: KINGFUL | B15: ACQUAH KOBINA | C15: 9696.55 | D15: B116709280059 | E15: kingfula@yahoo.com | F15: 0244624471 | I15: EMPLOYEE | M15: =_xlfn.IFNA(VLOOKUP(_xlfn.CONCAT(K15,L15),'Bank Data'!$CH$3:$CI$1508,2,0),"") | S15: MALE | T15: MARRIED | V15: Ghana | W15: GHANA CARD | X15: GHA-728079380-8 | Y15: NAF043 | AB15: 01/05/2015 | AC15: IMAGE AUDITOR | AF15: ICUMS | AH15: ICUMS | AI15: YES | AJ15: SALARY | AK15: GHS
A16: AKUA | B16: NANA FOSUA | C16: 1737.57 | E16: nanakadira54@gmail.com | F16: 0540988361 | I16: EMPLOYEE | M16: =_xlfn.IFNA(VLOOKUP(_xlfn.CONCAT(K16,L16),'Bank Data'!$CH$3:$CI$1508,2,0),"") | S16: FEMALE | V16: Ghana | W16: GHANA CARD | X16: GHA-724982985-2 | Y16: NAF214 | AB16: 01/11/2021 | AC16: OFFICE ASSISTANT | AF16: AFLAO | AH16: AFLAO | AI16: YES | AJ16: SALARY | AK16: GHS
A17: AMARTEY | B17: SOTTI | C17: 3161.91 | D17: D077605050130 | E17: tottieamartey@gmail.com | F17: 0206848005 | I17: EMPLOYEE | M17: =_xlfn.IFNA(VLOOKUP(_xlfn.CONCAT(K17,L17),'Bank Data'!$CH$3:$CI$1508,2,0),"") | S17: MALE | T17: SINGLE | V17: Ghana | W17: GHANA CARD | X17: GHA-728750571-6 | Y17: NKA110 | AB17: 01/02/2016 | AC17: DRIVER | AF17: TEMA | AH17: TEMA | AI17: YES | AJ17: SALARY | AK17: GHS
A18: ASMAWU | B18: MOHAMMED | C18: 4359 | D18: C018704130521 | E18: schimelda30@gmail.com | F18: 0243335576 | I18: EMPLOYEE | M18: =_xlfn.IFNA(VLOOKUP(_xlfn.CONCAT(K18,L18),'Bank Data'!$CH$3:$CI$1508,2,0),"") | S18: FEMALE | T18: MARRIED | V18: Ghana | W18: GHANA CARD | X18: GHA-002515850-6 | Y18: NKA137 | AB18: 01/02/2015 | AC18: IMAGE ANALYST | AF18: AIRPORT | AH18: AIRPORT | AI18: YES | AJ18: SALARY | AK18: GHS
A19: KWADWO | B19: AMISSAH OPOKU | C19: 7076 | D19: C017006240155 | I19: EMPLOYEE | M19: =_xlfn.IFNA(VLOOKUP(_xlfn.CONCAT(K19,L19),'Bank Data'!$CH$3:$CI$1508,2,0),"") | S19: MALE | V19: Ghana | W19: GHANA CARD | X19: GHA-001067885-1 | Y19: NTE185 | AB19: 01/02/2015 | AC19: SUPERVISOR | AF19: GHANA LINK | AH19: GHANA LINK | AI19: YES | AJ19: SALARY | AK19: GHS
A20: PONTIAC | B20: AYI | C20: 3771.91 | D20: G097908010056 | E20: akwakupontiac@gmail.com | I20: EMPLOYEE | M20: =_xlfn.IFNA(VLOOKUP(_xlfn.CONCAT(K20,L20),'Bank Data'!$CH$3:$CI$1508,2,0),"") | S20: MALE | V20: Ghana | W20: GHANA CARD | X20: GHA-713594758-0 | Y20: NAF048 | AB20: 01/11/2011 | AC20: TRAFFIC MARSHAL | AF20: AFLAO | AH20: AFLAO | AI20: YES | AJ20: SALARY | AK20: GHS
A21: GYASI | B21: ACHEAMPONG | C21: 2940.59 | D21: G099306020013 | E21: acheamponggyasi@gmail.com | F21: 0548068581 | I21: EMPLOYEE | M21: =_xlfn.IFNA(VLOOKUP(_xlfn.CONCAT(K21,L21),'Bank Data'!$CH$3:$CI$1508,2,0),"") | S21: MALE | V21: Ghana | W21: GHANA CARD | X21: GHA-715548139-3 | Y21: NKA229 | AC21: CHECK IN OFFICER | AF21: AIRPORT | AH21: AIRPORT | AI21: YES | AJ21: SALARY | AK21: GHS
A22: EMMA | B22: BAAH | C22: 4409.45 | D22: C017804210202 | E22: baahe067@gmail.com | F22: 0262685590 | I22: EMPLOYEE | M22: =_xlfn.IFNA(VLOOKUP(_xlfn.CONCAT(K22,L22),'Bank Data'!$CH$3:$CI$1508,2,0),"") | S22: FEMALE | V22: Ghana | W22: GHANA CARD | X22: GHA-000422388-3 | Y22: NTE174 | AB22: 01/11/2016 | AC22: CHECK IN OFFICER | AF22: AIRPORT | AH22: AIRPORT | AI22: YES | AJ22: SALARY | AK22: GHS
A23: ROSENKLE | B23: P. OFORI | C23: 5690.45 | D23: G097911110013 | E23: sosspanin@gmail.com | F23: 0244129875 | I23: EMPLOYEE | M23: =_xlfn.IFNA(VLOOKUP(_xlfn.CONCAT(K23,L23),'Bank Data'!$CH$3:$CI$1508,2,0),"") | S23: MALE | T23: MARRIED | V23: Ghana | W23: GHANA CARD | X23: GHA-720253575-4 | Y23: NTA029 | AB23: 02/02/2009 | AC23: IMAGE ANALYST | AF23: TAKORADI | AH23: TAKORADI | AI23: YES | AJ23: SALARY | AK23: GHS
A24: KWESI | B24: AFFUL MORRISON | C24: 3727.99 | D24: C107511160017 | F24: 0203494743 | I24: EMPLOYEE | M24: =_xlfn.IFNA(VLOOKUP(_xlfn.CONCAT(K24,L24),'Bank Data'!$CH$3:$CI$1508,2,0),"") | S24: MALE | T24: MARRIED | V24: Ghana | W24: GHANA CARD | X24: GHA-712126870-6 | Y24: NKA068 | AB24: 01/11/2011 | AC24: TRAFFIC MARSHAL | AF24: TEMA - SENTRY PORTAL | AH24: TEMA - SENTRY PORTAL | AI24: YES | AJ24: SALARY | AK24: GHS
A25: ANN | B25: BAFFOE | C25: 3391.54 | D25: G099810300024 | E25: baffoaann11@gmail.com | F25: 0507909742 | I25: EMPLOYEE | M25: =_xlfn.IFNA(VLOOKUP(_xlfn.CONCAT(K25,L25),'Bank Data'!$CH$3:$CI$1508,2,0),"") | S25: FEMALE | T25: SINGLE | V25: Ghana | W25: GHANA CARD | X25: GHA-726379417-8 | Y25: NTE208 | AB25: 01/11/2021 | AC25: SECRETARY | AF25: TEMA MAIN | AH25: TEMA MAIN | AI25: YES | AJ25: SALARY | AK25: GHS
A26: JOSEPH | B26: ATINGA APERIKA | C26: 1463.09 | D26: J019212220014 | E26: atingajoseph22@gmail.com | F26: 0549566865 | I26: EMPLOYEE | M26: =_xlfn.IFNA(VLOOKUP(_xlfn.CONCAT(K26,L26),'Bank Data'!$CH$3:$CI$1508,2,0),"") | S26: MALE | V26: Ghana | W26: GHANA CARD | X26: GHA-723286647-3 | Y26: NPA225 | AB26: 01/11/2021 | AC26: SECURITY | AF26: PAGA | AH26: PAGA | AI26: YES | AJ26: SALARY | AK26: GHS
A27: EMMANUEL | B27: EDEM NUKU | C27: 2984.51 | D27: R369705240013 | E27: edemnuku@gmail.com | F27: 0556283143 | I27: EMPLOYEE | M27: =_xlfn.IFNA(VLOOKUP(_xlfn.CONCAT(K27,L27),'Bank Data'!$CH$3:$CI$1508,2,0),"") | S27: MALE | V27: Ghana | W27: GHANA CARD | X27: GHA-727301828-2 | Y27: NKA160 | AB27: 04/07/2016 | AC27: CHECK IN OFFICER | AF27: AIRPORT | AH27: AIRPORT | AI27: YES | AJ27: SALARY | AK27: GHS
A28: SANI | B28: ALIDU AHMED | C28: 4658.4 | D28: C037106210039 | E28: ahsani.alidu@gmail.com | F28: 0240000016 | I28: EMPLOYEE | M28: =_xlfn.IFNA(VLOOKUP(_xlfn.CONCAT(K28,L28),'Bank Data'!$CH$3:$CI$1508,2,0),"") | S28: MALE | T28: MARRIED | V28: Ghana | W28: GHANA CARD | X28: GHA-001427133-9 | Y28: NTE194 | AC28: DRIVER | AF28: GHANA LINK | AH28: GHANA LINK | AI28: YES | AJ28: SALARY | AK28: GHS
A29: COLLINS | B29: OPOKU SEFAH | C29: 3527.91 | D29: G098407180016 | E29: collinsopoku135@gmail.com | F29: 0203278103 | I29: EMPLOYEE | M29: =_xlfn.IFNA(VLOOKUP(_xlfn.CONCAT(K29,L29),'Bank Data'!$CH$3:$CI$1508,2,0),"") | S29: MALE | V29: Ghana | W29: GHANA CARD | X29: GHA-726679782-8 | Y29: NTE104 | AB29: 04/03/2013 | AC29: TRAFFIC MARSHAL | AF29: TEMA - SENTRY PORTAL | AH29: TEMA - SENTRY PORTAL | AI29: YES | AJ29: SALARY | AK29: GHS
A30: RICHARD | B30: KROBILA | C30: 3217.51 | D30: C109007230172 | E30: rkrodilla@yahoo.com | F30: 0540867305 | I30: EMPLOYEE | M30: =_xlfn.IFNA(VLOOKUP(_xlfn.CONCAT(K30,L30),'Bank Data'!$CH$3:$CI$1508,2,0),"") | S30: MALE | T30: SINGLE | V30: Ghana | W30: GHANA CARD | X30: GHA-000986884-9 | Y30: NTAT01 | AB30: 01/09/2017 | AC30: IMAGE ANALYST | AF30: TEMA-SENTRY PORTAL | AH30: TEMA-SENTRY PORTAL | AI30: YES | AJ30: SALARY | AK30: GHS
A31: CECILIA | B31: KYEREWAA DANSO | C31: 4359 | D31: R368007220046 | E31: ceciliakyerewaa123@gmail.com | F31: 0241191657 | I31: EMPLOYEE | M31: =_xlfn.IFNA(VLOOKUP(_xlfn.CONCAT(K31,L31),'Bank Data'!$CH$3:$CI$1508,2,0),"") | S31: FEMALE | T31: MARRIED | V31: Ghana | W31: GHANA CARD | X31: GHA-001728672-7 | Y31: NTE027 | AB31: 29/09/2005 | AC31: OFFICE ASSISTANT | AF31: AIRPORT | AH31: AIRPORT | AI31: YES | AJ31: SALARY | AK31: GHS
A32: KWABENA | B32: GYASI | C32: 9093.81 | D32: F177909110058 | E32: kygyasi31@gmail.com | F32: 0244840874 | I32: EMPLOYEE | M32: =_xlfn.IFNA(VLOOKUP(_xlfn.CONCAT(K32,L32),'Bank Data'!$CH$3:$CI$1508,2,0),"") | S32: MALE | T32: MARRIED | V32: Ghana | W32: GHANA CARD | X32: GHA-002405291-5 | Y32: NTE014 | AB32: 01/10/2004 | AC32: ASSISTANT MANAGER AIRPORT | AF32: AIRPORT | AH32: AIRPORT | AI32: YES | AJ32: SALARY | AK32: GHS
A33: MARK | B33: KOFI ADADE NYASUNU | C33: 3405.91 | D33: A167302020012 | E33: marknyaseinu@gmail.com | F33: 0240505825 | I33: EMPLOYEE | M33: =_xlfn.IFNA(VLOOKUP(_xlfn.CONCAT(K33,L33),'Bank Data'!$CH$3:$CI$1508,2,0),"") | S33: MALE | T33: MARRIED | V33: Ghana | W33: GHANA CARD | X33: GHA-713689862-8 | Y33: NKA075 | AB33: 01/06/2012 | AC33: CLEANER/OFFICE ASSISTANT | AF33: AFLAO | AH33: AFLAO | AI33: YES | AJ33: SALARY | AK33: GHS
A34: PAA | B34: KWESI AHINKURAH | C34: 4154.87 | D34: C016508310058 | E34: pahinkurah@yahoo.com | F34: 0275452291 | I34: EMPLOYEE | M34: =_xlfn.IFNA(VLOOKUP(_xlfn.CONCAT(K34,L34),'Bank Data'!$CH$3:$CI$1508,2,0),"") | S34: MALE | T34: MARRIED | V34: Ghana | W34: GHANA CARD | X34: GHA-720215683-4 | Y34: NTA034 | AB34: 01/08/2007 | AC34: IMAGE ANALYST | AF34: TAKORADI | AH34: TAKORADI | AI34: YES | AJ34: SALARY | AK34: GHS
A35: KWAME | B35: FRIMPONG NTIAMOAH | C35: 1463.09 | D35: F069209190011 | E35: nanakwamefrimpong092@gmail.com | F35: 0248249033 | I35: EMPLOYEE | M35: =_xlfn.IFNA(VLOOKUP(_xlfn.CONCAT(K35,L35),'Bank Data'!$CH$3:$CI$1508,2,0),"") | S35: MALE | V35: Ghana | W35: GHANA CARD | X35: GHA-715335657-8 | Y35: NPA220 | AB35: 01/11/2021 | AC35: TRAFFIC MARSHAL | AF35: PAGE | AH35: PAGE | AI35: YES | AJ35: SALARY | AK35: GHS
A36: SIMON | B36: ASARE STONE | C36: 3527.91 | D36: G018610290117 | E36: de.stone2021@gmail.com | F36: 0243111658 | I36: EMPLOYEE | M36: =_xlfn.IFNA(VLOOKUP(_xlfn.CONCAT(K36,L36),'Bank Data'!$CH$3:$CI$1508,2,0),"") | S36: MALE | T36: MARRIED | V36: Ghana | W36: GHANA CARD | X36: GHA-713582875-8 | Y36: NAF153 | AB36: 01/02/2016 | AC36: IMAGE ANALYST | AF36: AFLAO | AH36: AFLAO | AI36: YES | AJ36: SALARY | AK36: GHS
A37: BRIGHT | B37: ADU AGYAPONG | C37: 4897.45 | D37: F018506060359 | E37: rockyjbright@yahoo.com | F37: 0243236552 | I37: EMPLOYEE | M37: =_xlfn.IFNA(VLOOKUP(_xlfn.CONCAT(K37,L37),'Bank Data'!$CH$3:$CI$1508,2,0),"") | S37: MALE | T37: MARRIED | V37: Ghana | W37: GHANA CARD | X37: GHA-729090384-2 | Y37: NTE080 | AB37: 01/06/2012 | AC37: CHECK IN OFFICER | AF37: AIRPORT | AH37: AIRPORT | AI37: YES | AJ37: SALARY | AK37: GHS
A38: AUGUSTINE | B38: OSEI | C38: 3039.91 | D38: G018505290075 | E38: augustuneosei40@gmail.com | F38: 0248611018 | I38: EMPLOYEE | M38: =_xlfn.IFNA(VLOOKUP(_xlfn.CONCAT(K38,L38),'Bank Data'!$CH$3:$CI$1508,2,0),"") | S38: MALE | V38: Ghana | W38: GHANA CARD | X38: GHA-712158808-2 | Y38: NKA139 | AB38: 02/01/2014 | AC38: TRAFFIC MARSHAL | AF38: AIRPORT | AH38: AIRPORT | AI38: YES | AJ38: SALARY | AK38: GHS
A39: SAMUEL | B39: ANTWI | C39: 1480.61 | D39: G099305250070 | E39: samuelantwikwadwo@gmail.com | F39: 0551826186 | I39: EMPLOYEE | M39: =_xlfn.IFNA(VLOOKUP(_xlfn.CONCAT(K39,L39),'Bank Data'!$CH$3:$CI$1508,2,0),"") | S39: MALE | V39: Ghana | W39: GHANA CARD | X39: GHA-725457015-2 | Y39: NTE218 | AB39: 01/11/2021 | AC39: TRAFFIC MARSHAL | AF39: TEMA - SENTRY PORTAL | AH39: TEMA - SENTRY PORTAL | AI39: YES | AJ39: SALARY | AK39: GHS
A40: GENEVIEVE | B40: ADDY | C40: 5189.05 | D40: C038403210084 | E40: Naa18addy@yahoo.com | F40: 0244845465 | I40: EMPLOYEE | M40: =_xlfn.IFNA(VLOOKUP(_xlfn.CONCAT(K40,L40),'Bank Data'!$CH$3:$CI$1508,2,0),"") | S40: FEMALE | T40: MARRIED | V40: Ghana | W40: GHANA CARD | X40: GHA-000224347-0 | Y40: NKA132 | AB40: 02/04/2014 | AC40: SECRETARY | AF40: AIRPORT | AH40: AIRPORT | AI40: YES | AJ40: SALARY | AK40: GHS
...

Sheet Bank Data
A2: BankName | C2: Absa (GH) LTD Branches | D2: Absa (GH) LTD BankBranchCode | F2: Access Bank (Ghana) Plc Branches | G2: Access Bank (Ghana) Plc BankBranchCode | I2: Agricultural Development Bank Limited Branches | J2: Agricultural Development Bank Limited BankBranchCode | L2: Apex Bank GH Limited Branches | M2: Apex Bank GH Limited BankBranchCode | O2: Bank of Africa Ghana Limited | P2: Bank of Africa Ghana Limited BankBranchCode | R2: Bank of Ghana | S2: Bank of Ghana BankBranchCode | U2: BSIC Ghana Limited | V2: BSIC Ghana Limited BankBranchCode | X2: CAL Bank Limited | Y2: CAL Bank Limited BankBranchCode | AA2: Consolidated Bank Ghana Limited | AB2: Consolidated Bank Ghana Limited BankBranchCode | AD2: Ecobank Ghana Limited | AE2: Ecobank Ghana Limited BankBranchCode | AG2: FBN Bank (Ghana) Limited | AH2: FBN Bank (Ghana) Limited BankBranchCode | AJ2: Fidelity Bank Limited | AK2: Fidelity Bank Limited BankBranchCode | AM2: First Atlantic Bank Limited | AN2: First Atlantic Bank Limited BankBranchCode | AP2: First National Bank (Ghana) Limited | AQ2: First National Bank (Ghana) Limited | AS2: GCB Bank Limited | AT2: GCB Bank Limited BankBranchCode | AV2: GHL Bank Limited | AW2: GHL Bank Limited BankBranchCode | AZ2: Guaranty Trust Bank (Ghana) Limited | BA2: Guaranty Trust Bank (Ghana) Limited BankBranchCode | BC2: National Investment Bank Limited | BD2: National Investment Bank Limited BankBranchCode | BF2: Omni Bank Ghana Limited | BG2: Omni Bank Ghana Limited BankBranchCode | BI2: Prudential Bank Limited | BJ2: Prudential Bank Limited BankBranchCode | BL2: Republic Bank (Ghana) Limited | BM2: Republic Bank (Ghana) Limited BankBranchCode | BO2: Societe General (Ghana) Limited | BP2: Societe General (Ghana) Limited BankBranchCode | BR2: Stanbic Bank Ghana Limited | BS2: Stanbic Bank Ghana Limited BankBranchCode | BU2: Standard Chartered Bank (Ghana) Limited | BV2: Standard Chartered Bank (Ghana) Limited BankBranchName | BX2: United Bank for Africa (Ghana) Limited | BY2: United Bank for Africa (Ghana) Limited BankBranchCode | CA2: Universal Merchant Bank Limited | CB2: Universal Merchant Bank Limited BankBranchCode | CD2: Zenith Bank (Ghana) Limited | CE2: Zenith Bank (Ghana) Limited BankBranchCode | CH2: ALL BANK BRANCHES | CI2: BRANCH CODE
A3: Absa (GH) LTD | C3: BARCLAYS BANK OF GHANA LIMITED | D3: 30100 | F3: HEAD OFFICE | G3: 280100 | I3: CORPORATE BANKING | J3: 80010 | L3: ARB APEX BANK/RURAL & COMMUNITY BANKS | M3: 70100 | O3: HEAD OFFICE | P3: 210100 | R3: HEAD OFFICE | S3: 10100 | U3: BSIC BANK | V3: 270100 | X3: HEAD OFFICE | Y3: 140100 | AA3: HEAD OFFICE | AB3: 340100 | AD3: ECOBANK GHANA LIMITED | AE3: 130100 | AG3: FBN BANK (GHANA) LIMITED | AH3: 200100 | AJ3: WOMEN'S WORLD BANK GHANA SAVINGS AND LOANS | AK3: 170170 | AM3: FIRST ATLANTIC BANK LIMITED | AN3: 170100 | AP3: FIRST ATLANTIC BANK LTD - GLOBAL ACCESS S-L | AQ3: 170178 | AS3: WA | AT3: 40001 | AV3: HEAD OFFICE | AW3: 390100 | AZ3: GUARANTY TRUST BANK (GHANA) LIMITED | BA3: 230100 | BC3: NATIONAL INVESTMENT BANK | BD3: 50100 | BF3: OMNI BANK GHANA LIMITED | BG3: 360100 | BI3: PRUDENTIAL BANK | BJ3: 180100 | BL3: REPUBLIC BANK (GHANA) LIMITED | BM3: 110100 | BO3: SOCIETE GENERALE GHANA LTD | BP3: 90100 | BR3: STANBIC BANK GHANA LIMITED | BS3: 190100 | BU3: STANDARD CHARTERED BANK (GHANA) LIMITED | BV3: 20100 | BX3: UNITED BANK FOR AFRICA (GHANA) LIMITED | BY3: 60100 | CA3: KANESHIE | CB3: 100105 | CD3: ZENITH BANK (GHANA) LIMITED | CE3: 120100 | CH3: Absa (GH) LTDBARCLAYS BANK OF GHANA LIMITED | CI3: 30100
A4: Access Bank (Ghana) Plc | C4: KASOA | D4: 30101 | F4: EAST CANTONMENTS BRANCH | G4: 280101 | I4: CONSUMER BANKING | J4: 80020 | L4: HEAD OFFICE-SOUTH RIDGE ACCRA | M4: 70101 | O4: FARRAR | P4: 210101 | R4: ACCRA | S4: 10101 | U4: ADABRAKA | V4: 270101 | X4: INDEPENDENCE AVENUE | Y4: 140101 | AA4: AIRPORT CITY BRANCH | AB4: 340101 | AD4: HEAD OFFICE | AE4: 130101 | AG4: MAKOLA | AH4: 200101 | AJ4: MULTICREDIT SAVINGS & LOANS LIMITED | AK4: 170650 | AM4: HEAD OFFICE | AN4: 170101 | AP4: FIRST NATIONAL BANK (GHANA) LIMITED | AQ4: 330100 | AS4: TUMU | AT4: 40002 | AV4: AIRPORT CITY BRANCH | AW4: 390101 | AZ4: HEAD OFFICE | BA4: 230101 | BC4: ACCRA MAIN | BD4: 50101 | BF4: HEAD OFFICE | BG4: 360101 | BI4: ACCRA | BJ4: 180101 | BL4: EBANKESE | BM4: 110101 | BO4: ACCRA MAIN | BP4: 90101 | BR4: ACCRA MAIN | BS4: 190101 | BU4: HIGH STREET | BV4: 20101 | BX4: HEAD OFFICE-RIDGE | BY4: 60101 | CA4: ABEKA BRANCH | CB4: 100106 | CD4: PREMIER TOWERS | CE4: 120101 | CH4: Absa (GH) LTDKASOA | CI4: 30101
A5: Agricultural Development Bank Limited | C5: A AND C MALL | D5: 30104 | F5: TEMA MAIN BRANCH | G5: 280102 | I5: PARASTATALS | J5: 80030 | L5: APEX BANKACCRA CENTRE-ACCRA | M5: 70102 | O5: RIDGE | P5: 210102 | R5: BANK OF GHANA WEST-TEST | S5: 10122 | U5: ACCRA CENTRAL | V5: 270102 | X5: TEMA | Y5: 140102 | AA5: RIDGE BRANCH | AB5: 340102 | AD5: TEMA | AE5: 130102 | AG5: KASOA | AH5: 200102 | AJ5: DORMAA CREDIT UNION | AK5: 240087 | AM5: KANTAMANTO AGENCY | AN5: 170102 | AP5: JUNCTION SHOPPING CENTRE | AQ5: 330101 | AS5: LAWRA | AT5: 40003 | AV5: TAKORADI BRANCH | AW5: 390401 | AZ5: AIRPORT | BA5: 230102 | BC5: TEMA MAIN | BD5: 50109 | BF5: ABOSSEY OKAI | BG5: 360102 | BI5: ABOSSEY OKAI | BJ5: 180102 | BL5: ACCRA CENTRAL | BM5: 110103 | BO5: NORTH INDUSTRIAL AREA | BP5: 90102 | BR5: AIRPORT CITY | BS5: 190102 | BU5: INDEPENDENCE AVENUE | BV5: 20102 | BX5: ACCRA CENTRAL | BY5: 60102 | CA5: NORTH INDUSTRIAL | CB5: 100107 | CD5: PATRICE LUMUMBA ROAD | CE5: 120102 | CH5: Absa (GH) LTDA AND C MALL | CI5: 30104
A6: Apex Bank GH Limited | C6: ACCRA MALL | D6: 30105 | F6: OSU OXFORD BRANCH | G6: 280103 | I6: AGRIC FINANCING | J6: 80040 | L6: NYAKROM RURAL BANK LTD-NYAKROM | M6: 70103 | O6: MAAMOBI | P6: 210103 | R6: AGONA SWEDRU | S6: 10303 | U6: SPINTEX | V6: 270103 | X6: DERBY AVENUE | Y6: 140103 | AA6: TUDU BRANCH | AB6: 340103 | AD6: RING ROAD CENTRAL | AE6: 130103 | AG6: TEMA | AH6: 200103 | AJ6: GOLDEN PRIDE SAVINGS & LOANS | AK6: 240091 | AM6: TEMA | AN6: 170103 | AP6: ACCRA | AQ6: 330102 | AS6: BOLE | AT6: 40004 | AV6: KUMASI BRANCH | AW6: 390601 | AZ6: TEMA | BA6: 230103 | BC6: OSU | BD6: 50111 | BF6: ASHAIMAN | BG6: 360103 | BI6: GICEL | BJ6: 180103 | BL6: RIDGE | BM6: 110104 | BO6: TUDU | BP6: 90103 | BR6: SPINTEX ROAD | BS6: 190103 | BU6: LIBERIA ROAD | BV6: 20104 | BX6: TEMA | BY6: 60103 | CA6: TEMA EAST | CB6: 100108 | CD6: TEMA COMMUNITY 1 | CE6: 120103 | CH6: Absa (GH) LTDACCRA MALL | CI6: 30105
A7: Bank of Africa Ghana Limited | C7: ABEKA LAPAZ | D7: 30106 | F7: LASHIBI BRANCH | G7: 280104 | I7: COMMERCIAL BANKING | J7: 80050 | L7: MANYA KROBO RURAL BANK LTD-ODUMASE-KROBO | M7: 70104 | O7: ACCRA CENTRAL | P7: 210104 | R7: TAKORADI | S7: 10401 | U7: NIMA | V7: 270104 | X7: SPINTEX ROAD | Y7: 140104 | AA7: TEMA COMMUNITY 1 BRANCH | AB7: 340104 | AD7: TUDU | AE7: 130104 | AG7: KANESHIE | AH7: 200104 | AJ7: SINAPI ABA SAVINGS & LOANS | AK7: 240092 | AM7: MAKOLA | AN7: 170104 | AP7: ACCRA MALL | AQ7: 330106 | AS7: GCB BANK LIMITED | AT7: 40100 | AZ7: OSU | BA7: 230104 | BC7: FOREIGN | BD7: 50112 | BF7: DZORWULU | BG7: 360104 | BI7: TEMA FISHING HABOUR | BJ7: 180104 | BL7: TEMA | BM7: 110105 | BO7: ACCRA NEW TOWN | BP7: 90104 | BR7: ACCRA MALL | BS7: 190104 | BU7: OPEIBEA HOUSE | BV7: 20105 | BX7: ABOSSEYOKAI | BY7: 60104 | CA7: ACHIMOTA | CB7: 100109 | CD7: KOJO THOMPSON ROAD BRANCH | CE7: 120104 | CH7: Absa (GH) LTDABEKA LAPAZ | CI7: 30106
A8: Bank of Ghana | C8: DANSOMAN | D8: 30107 | F8: OSU WATSON BRANCH | G8: 280105 | I8: AGRIC VALUE CHAIN | J8: 80060 | L8: GOMOA RURAL BANK LTD-APAM | M8: 70105 | O8: NEWTOWN | P8: 210105 | R8: SEFWI BOAKO | S8: 10402 | U8: NORTH INDUSTRIAL AREA | V8: 270105 | X8: GRAPHIC ROAD | Y8: 140105 | AA8: ACCRA CENTRAL BRANCH | AB8: 340105 | AD8: SILVER STAR | AE8: 130105 | AG8: RING ROAD CENTRAL | AH8: 200105 | AJ8: UTRAK SAVINGS AND LOANS | AK8: 240093 | AM8: NORTH RIDGE | AN8: 170105 | AP8: ACHIMOTA MALL | AQ8: 330107 | AS8: HIGH STREET | AT8: 40101 | AZ8: SPINTEX ROAD | BA8: 230105 | BC8: TEMA HABOUR AREA(AFKO) | BD8: 50113 | BF8: DOME | BG8: 360105 | BI8: MADINA | BJ8: 180105 | BL8: LEGON | BM8: 110107 | BO8: FAANOFA | BP8: 90105 | BR8: NORTH INDUSTIAL AREA | BS8: 190105 | BU8: TEMA | BV8: 20106 | BX8: RING ROAD | BY8: 60107 | CA8: ABOSEY OKAI | CB8: 100110 | CD8: SPINTEX | CE8: 120105 | CH8: Absa (GH) LTDDANSOMAN | CI8: 30107
A9: BSIC Ghana Limited | C9: GNPC | D9: 30108 | F9: KANTAMANTO BRANCH | G9: 280106 | I9: BUSINESS FINANCE | J9: 80070 | L9: ANUM RURAL BANK LTD-ANUM | M9: 70106 | O9: MICHEL CAMP | P9: 210106 | R9: KUMASI | S9: 10601 | U9: MADINA | V9: 270106 | X9: TEMA HARBOUR | Y9: 140106 | AA9: MAKOLA BRANCH | AB9: 340106 | AD9: OSU | AE9: 130106 | AG9: DANSOMAN | AH9: 200106 | AJ9: ABII NATIONAL SAVINGS AND LOANS LTD | AK9: 240094 | AM9: SPINTEX BRANCH | AN9: 170107 | AP9: WEST HILLS MALL | AQ9: 330108 | AS9: BURMA CAMP | AT9: 40102 | AZ9: LABONE | BA9: 230106 | BC9: LOTTERIES | BD9: 50116 | BF9: NMAI-DJORN | BG9: 360106 | BI9: MAKOLA | BJ9: 180107 | BL9: ABOSEY OKAI | BM9: 110108 | BO9: TEMA COMMUNITY TWO | BP9: 90106 | BR9: TEMA INDUSTRIAL AREA | BS9: 190106 | BU9: TUDU | BV9: 20107 | BX9: DZORWULU 1 MOTORWAY | BY9: 60108 | CA9: SOUTH INDUSTRIAL AREA | CB9: 100111 | CD9: GRAPHIC ROAD | CE9: 120106 | CH9: Absa (GH) LTDGNPC | CI9: 30108
A10: CAL Bank Limited | C10: NIMA | D10: 30109 | F10: KANESHIE BRANCH | G10: 280107 | I10: HEAD OFFICE | J10: 80100 | L10: AKUAPEM RURAL BANK LTD-MAMFE | M10: 70107 | O10: EAST LEGON | P10: 210111 | R10: SUNYANI | S10: 10701 | U10: TEMA | V10: 270107 | X10: WEIJA BRANCH | Y10: 140107 | AA10: ARENA BRANCH | AB10: 340107 | AD10: A AND C | AE10: 130107 | AG10: SPINTEX ROAD | AH10: 200107 | AJ10: BOND SAVINGS AND LOANS | AK10: 240095 | AM10: AIRPOT BRANCH | AN10: 170108 | AP10: MAKOLA | AQ10: 330111 | AS10: LEGON | AT10: 40103 | AZ10: GRAPHIC ROAD | BA10: 230107 | BC10: ABEKA | BD10: 50117 | BF10: TEMA 1 | BG10: 360107 | BI10: RING ROAD CENTRAL | BJ10: 180109 | BL10: TUDU | BM10: 110109 | BO10: OSU | BP10: 90107 | BR10: GRAPHIC ROAD | BS10: 190107 | BU10: LEGON | BV10: 20108 | BX10: DZORWULU 2 | BY10: 60109 | CA10: OSU | CB10: 100112 | CD10: NORTH INDUSTRIAL AREA | CE10: 120107 | CH10: Absa (GH) LTDNIMA | CI10: 30109
A11: Consolidated Bank Ghana Limited | C11: LEGON | D11: 30110 | F11: CASTLE ROAD BRANCH | G11: 280108 | I11: RING ROAD CENTRAL | J11: 80101 | L11: DANGBE RURAL BANK LTD-PRAMPRAM | M11: 70108 | O11: KWASHIEMAN | P11: 210112 | R11: TAMALE | S11: 10801 | U11: DARKUMAN | V11: 270108 | X11: CIRCLE BRANCH | Y11: 140108 | AA11: KOKOMLEMLE | AB11: 340108 | AD11: TEMA LONG ROOM | AE11: 130108 | AG11: SWEDRU | AH11: 200108 | AJ11: PAY HUB | AK11: 240096 | AM11: ABOSSEY OKAI BRANCH | AN11: 170109 | AP11: TEMA | AQ11: 330112 | AS11: MINISTRIES | AT11: 40105 | AZ11: ASHIAMAN | BA11: 230108 | BC11: CLEARING UNIT | BD11: 50120 | BF11: KOKOMLEMLE | BG11: 360108 | BI11: SPINTEX ROAD | BJ11: 180110 | BL11: AGBOGBLOSHIE | BM11: 110112 | BO11: OKAISHIE | BP11: 90108 | BR11: MAKOLA | BS11: 190108 | BU11: OSU | BV11: 20112 | BX11: MADINA | BY11: 60110 | CA11: JUNCTION MALL BRANCH | CB11: 100115 | CD11: LABONE | CE11: 120108 | CH11: Absa (GH) LTDLEGON | CI11: 30110
A12: Ecobank Ghana Limited | C12: ACHIMOTA | D12: 30111 | F12: ACCESS BANK -MADINA BRANCH | G12: 280109 | I12: ADABRAKA | J12: 80102 | L12: SHAI RURAL BANK LTD-DODOWA | M12: 70109 | O12: OSU | P12: 210113 | R12: HOHOE | S12: 11101 | U12: ACHIMOTA | V12: 270109 | X12: LEGON | Y12: 140109 | AA12: ACHITOMA BRANCH | AB12: 340109 | AD12: MCCARTHY HILL | AE12: 130109 | AG12: ACHIMOTA | AH12: 200109 | AJ12: PROCREDIT SAVINGS AND LOANS COMPANY LTD | AK12: 240097 | AM12: NORTH INDUSTRIAL AREA | AN12: 170110 | AS12: REPUBLIC HOUSE | AT12: 40106 | AZ12: TUDU | BA12: 230109 | BC12: ADENTA | BD12: 50122 | BF12: MADINA | BG12: 360109 | BI12: TEMA COMMUNITY 1 | BJ12: 180111 | BL12: BAATSONA | BM12: 110116 | BO12: KANASHIE | BP12: 90109 | BR12: RIND ROAD | BS12: 190109 | BU12: SPINTEX | BV12: 20118 | BX12: EAST LEGON 1 | BY12: 60111 | CA12: UNIVERSAL EAST LEGON BRANCH | CB12: 100116 | CD12: EAST LEGON | CE12: 120109 | CH12: Absa (GH) LTDACHIMOTA | CI12: 30111
A13: FBN Bank (Ghana) Limited | C13: OSU | D13: 30112 | F13: SOUTH INDUSTRIAL BRANCH | G13: 280110 | I13: TEMA | J13: 80103 | L13: ADA RURAL BANK LTD-KASSEH | M13: 70110 | O13: SPINTEX ROAD | P13: 210114 | U13: TAKORADI | V13: 270401 | X13: RING ROAD CENTRAL | Y13: 140110 | AA13: ADABRAKA BRANCH | AB13: 340110 | AD13: ROMAN RIDGE BRANCH | AE13: 130110 | AG13: SWANMILL | AH13: 200110 | AJ13: ALPHA CAPITAL SAVING&L LTD | AK13: 240098 | AM13: OSU OXFORD STREET BRANCH | AN13: 170111 | AS13: TEMA MAIN | AT13: 40107 | AZ13: MADINA | BA13: 230110 | BC13: SPINTEX | BD13: 50123 | BF13: TUDU | BG13: 360110 | BI13: WEIJA | BJ13: 180112 | BL13: PRIVATE BANKING | BM13: 110117 | BO13: TEMA FISHING HARBOUR | BP13: 90110 | BR13: ACHIMOTA | BS13: 190110 | BU13: DANSOMAN | BV13: 20121 | BX13: EAST LEGON 2 | BY13: 60112 | CA13: OXFORD STREET | CB13: 100117 | CD13: TEMA INDUSTRIAL AREA | CE13: 120110 | CH13: Absa (GH) LTDOSU | CI13: 30112
A14: Fidelity Bank Limited | C14: RING ROAD CENTRAL | D14: 30114 | F14: NIA BRANCH | G14: 280111 | I14: TESHIE | J14: 80104 | L14: BRAKWA BRAMAN RURAL BANK LTD-BRAKWA | M14: 70111 | O14: TEMA | P14: 210116 | U14: KUMASI | V14: 270601 | X14: ACHIMOTA | Y14: 140111 | AA14: ADENTA BRANCH | AB14: 340111 | AD14: ABEKA LAPAZ | AE14: 130111 | AG14: KORLE-BU | AH14: 200111 | AJ14: SOVEREIGN BANK LIMITED | AK14: 240099 | AM14: WEIJA BRANCH | AN14: 170113 | AS14: TEMA MARKET | AT14: 40108 | AZ14: ACHIMOTA | BA14: 230111 | BC14: WINNEBA ROAD | BD14: 50124 | BF14: SPINTEX | BG14: 360111 | BI14: TESANO | BJ14: 180113 | BL14: ASHIAMAN | BM14: 110118 | BO14: KOTOBABI | BP14: 90111 | BR14: ROMAN RIDGE | BS14: 190111 | BU14: ABEKA | BV14: 20126 | BX14: TESHIE | BY14: 60113 | CA14: SPINTEX ROAD | CB14: 100118 | CD14: ACHIMOTA BRANCH | CE14: 120111 | CH14: Absa (GH) LTDRING ROAD CENTRAL | CI14: 30114
A15: First Atlantic Bank Limited | C15: BCM | D15: 30116 | F15: RING ROAD CENTRAL BRANCH | G15: 280112 | I15: KANESSHIE | J15: 80105 | L15: EASTERN GOMOA ASSIN RURAL BANK LTD-GOMOA-DOMINASE | M15: 70112 | O15: DANSOMAN | P15: 210117 | U15: KUMASI (ALABAR) | V15: 270602 | X15: OSU | Y15: 140112 | AA15: SPINTEX BRANCH | AB15: 340112 | AD15: DANSOMAN | AE15: 130112 | AG15: DOME | AH15: 200112 | AJ15: HEAD OFFICE | AK15: 240100 | AM15: EAST LEGON MAIN BRANCH | AN15: 170114 | AS15: TEMA INDUSTRIAL AREA | AT15: 40109 | AZ15: NIA | BA15: 230112 | BC15: NORTH INDUSTRIAL AREA | BD15: 50128 | BF15: OSU | BG15: 360112 | BI15: ZONGO JUNCTION | BJ15: 180114 | BL15: POST OFFICE SQUARE | BM15: 110119 | BO15: PREMIER TOWERS | BP15: 90114 | BR15: KASOA | BS15: 190112 | BU15: ACHIMOTA | BV15: 20127 | BX15: SPINTEX ROAD | BY15: 60114 | CA15: MADINA | CB15: 100122 | CD15: AKOSOMBO BRANCH | CE15: 120112 | CH15: Absa (GH) LTDBCM | CI15: 30116
A16: First National Bank (Ghana) Limited | C16: MOTORWAY EXT | D16: 30117 | F16: KANESHIE POST OFFICE BRANCH | G16: 280113 | I16: CEDI HOUSE | J16: 80106 | L16: GOMOA AJUMAKO RURAL BANK LTD-AFRANSI | M16: 70113 | O16: MADINA | P16: 210118 | U16: TAMALE | V16: 270801 | X16: COMMUNITY 25 | Y16: 140113 | AA16: AMERICAN HOUSE BRANCH | AB16: 340113 | AD16: TEMA COMMUNITY 6 | AE16: 130113 | AG16: SANTA MARIA | AH16: 200113 | AJ16: RIDGE TOWERS | AK16: 240101 | AM16: KOTOBABI BRANCH | AN16: 170115 | AS16: TEMA FISHING HARBOUR | AT16: 40110 | AZ16: COMMUNITY 6 | BA16: 230113 | BC16: TEMA COMMUNITY 9 | BD16: 50129 | BF16: WEIJA | BG16: 360113 | BI16: ODORKOR | BJ16: 180115 | BL16: ADABRAKA BRANCH | BM16: 110120 | BO16: HEAD OFFICE | BP16: 90115 | BR16: TEMA FISHING HABOUR | BS16: 190113 | BU16: NIA | BV16: 20129 | BX16: NORTH INDUSTRIAL AREA BUSINESS OFFICE | BY16: 60127 | CA16: BAYPORT SAVINGS & LOANS LTD | CB16: 100138 | CD16: TEMA METRO BRANCH | CE16: 120113 | CH16: Absa (GH) LTDMOTORWAY EXT | CI16: 30117
A17: GCB Bank Limited | C17: SPINTEX MAIN | D17: 30121 | F17: ABEKA LAPAZ BRANCH | G17: 280114 | I17: ADB -INTERNATIONAL BANKING | J17: 80107 | L17: AGONA RURAL BANK LTD-KWANYAKU | M17: 70114 | O17: ABOSSEY OKAI | P17: 210119 | X17: EAST LEGON BRANCH | Y17: 140114 | AA17: ANYAA BRANCH | AB17: 340114 | AD17: DARKUMAN | AE17: 130114 | AG17: SPINTEX 2 BRANCH | AH17: 200114 | AJ17: SPINTEX ROAD | AK17: 240102 | AM17: SAKUMONO BRANCH | AN17: 170116 | AS17: RING ROAD WEST | AT17: 40111 | AZ17: OPERA SQUARE | BA17: 230114 | BC17: HEAD OFFICE | BD17: 50131 | BF17: EAST LEGON | BG17: 360114 | BI17: ABEKA | BJ17: 180116 | BL17: DANSOMAN BRANCH | BM17: 110121 | BO17: SPINTEX ROAD | BP17: 90117 | BR17: MOVENPICK | BS17: 190114 | BU17: WESTLANDS | BV17: 20131 | BX17: ACHIMOTA | BY17: 60129 | CA17: NDK FINANCIAL SERVICES | CB17: 100140 | CD17: FREE ZONES BRANCH | CE17: 120114 | CH17: Absa (GH) LTDSPINTEX MAIN | CI17: 30121
A18: GHL Bank Limited | C18: KNUTSFORD AVENUE | D18: 30122 | F18: OKAISHIE BRANCH | G18: 280115 | I18: GULF HOUSE | J18: 80108 | L18: AKYEPIM RURAL BANK LTD-GOMOA-DAW | M18: 70115 | O18: TAKORADI | P18: 210401 | X18: DANSOMAN | Y18: 140115 | AA18: APENKWA BRANCH | AB18: 340115 | AD18: LEGON | AE18: 130115 | AG18: AIRPORT BRANCH | AH18: 200115 | AJ18: HIGH STREET | AK18: 240103 | AM18: SAKAMAN | AN18: 170119 | AS18: KANESHIE MARKET | AT18: 40112 | AZ18: LAPAZ | BA18: 230115 | BC18: DANSOMAN | BD18: 50132 | BF18: TEMA 2 | BG18: 360115 | BI18: NORTH INDUSTRIAL AREA | BJ18: 180117 | BL18: ACCRA NEW TOWN | BM18: 110122 | BO18: MADINA | BP18: 90118 | BR18: MADINA | BS18: 190115 | BU18: TEMA HABOUR | BV18: 20132 | BX18: THE SEED SAVINGS AND LOANS | BY18: 60150 | CA18: INNOVATION AGAINST POVERTY | CB18: 100141 | CD18: TRADE FAIR BRANCH | CE18: 120115 | CH18: Absa (GH) LTDKNUTSFORD AVENUE | CI18: 30122
A19: Guaranty Trust Bank (Ghana) Limited | C19: LEGON MAIN | D19: 30125 | F19: ASHAIMAN BRANCH | G19: 280116 | I19: DANSOMAN | J19: 80109 | L19: AWUTU EMASA RURAL BANK LTD-AWUMASA | M19: 70116 | O19: KUMASI AMAKOM | P19: 210601 | X19: LABONE | Y19: 140116 | AA19: ASHAIMAN ROUND ABOUT | AB19: 340116 | AD19: SOUTH INDUSTRIAL AREA(SIA) | AE19: 130116 | AG19: TAKORADI | AH19: 200401 | AJ19: OSU | AK19: 240104 | AM19: DWORWULU | AN19: 170120 | AS19: KORLEBU | AT19: 40113 | AZ19: EAST LEGON | BA19: 230116 | BC19: ASHAIMAN BRANCH | BD19: 50134 | BF19: KOFORIDUA | BG19: 360201 | BI19: ADENTA | BJ19: 180118 | BL19: MADINA | BM19: 110123 | BO19: KASOA | BP19: 90119 | BR19: DANSOMAN | BS19: 190116 | BU19: WESTHILLS | BV19: 20133 | BX19: GOLDEN LINK SAVINGS & LOANS | BY19: 60170 | CA19: INTERNATIONAL NEEDS LIMITED | CB19: 100142 | CD19: SAKAMAN BRANCH | CE19: 120116 | CH19: Absa (GH) LTDLEGON MAIN | CI19: 30125
A20: National Investment Bank Limited | C20: TEMA FISHING HARBOUR | D20: 30130 | F20: IPS BRANCH | G20: 280117 | I20: NUNGUA | J20: 80110 | L20: GA RURAL BANK LTD-AMASAMAN | M20: 70117 | O20: KUMASI -ADUM | P20: 210602 | X20: AIRPORT CITY BRANCH | Y20: 140117 | AA20: ASHAIMAN MAIN BRANCH | AB20: 340117 | AD20: SPINTEX | AE20: 130117 | AG20: ADUM | AH20: 200601 | AJ20: ABOSSEY OKAI | AK20: 240105 | AM20: RING ROAD | AN20: 170121 | AS20: OSU | AT20: 40114 | AZ20: DOME | BA20: 230117 | BC20: AIRPORT CITY | BD20: 50135 | BF20: KASOA | BG20: 360301 | BI20: KWAME NKRUMAH CIRCLE | BJ20: 180119 | BL20: ACHIMOTA | BM20: 110124 | BO20: TEMA COMMUNITY ONE | BP20: 90120 | BR20: ASHAIMAN | BS20: 190117 | BU20: LIBERIA ROAD TAKORADI | BV20: 20436 | BX20: TAKORADI | BY20: 60402 | CA20: SAHAM LIFE LIMITED | CB20: 100143 | CD20: PREMIER TOWERS BRANCH | CE20: 120117 | CH20: Absa (GH) LTDTEMA FISHING HARBOUR | CI20: 30130
A21: Omni Bank Ghana Limited | C21: MAKOLA SQUARE | D21: 30135 | F21: ACHIMOTA BRANCH | G21: 280118 | I21: KORKORDZOR | J21: 80111 | L21: ABOKOBI RURAL BANK LTD-ABOKOBI | M21: 70118 | O21: SOKOBAN | P21: 210603 | X21: AIRPORT REFINERY | Y21: 140118 | AA21: ASHALLEY BOTWE BRANCH | AB21: 340118 | AD21: ACCRA SHOPPING MALL | AE21: 130118 | AG21: SUAME | AH21: 200602 | AJ21: TEMA SAFE BOND | AK21: 240106 | AM21: MADINA | AN21: 170122 | AS21: DERBY AVENUE | AT21: 40115 | AZ21: MAKOLA | BA21: 230118 | BC21: EAST LEGON | BD21: 50136 | BF21: TAKORADI | BG21: 360401 | BI21: MATAHEKO | BJ21: 180120 | BL21: LEGON ANNEX BRANCH | BM21: 110125 | BO21: ASHAIMAN | BP21: 90121 | BR21: TEMA COMMUNITY ONE | BS21: 190118 | BU21: KNUST | BV21: 20611 | BX21: TARKWA | BY21: 60403 | CA21: VANGUARD ASSURANCE | CB21: 100144 | CD21: KOFORIDUA BRANCH | CE21: 120201 | CH21: Absa (GH) LTDMAKOLA SQUARE | CI21: 30135
A22: Prudential Bank Limited | C22: AIRPORT CITY | D22: 30136 | F22: TEMA COMMUNITY 1 BRANCH | G22: 280119 | I22: OSU | J22: 80112 | L22: BAWJIASE AREA RURAL BANK LTD-AWUTU BAWJIASE | M22: 70119 | O22: MULTICREDIT SAVINGS AND LOANS CO. | P22: 210699 | X22: EMAN CAPITAL MICROFINANCE LTD | Y22: 140189 | AA22: ASHIYE BRANCH | AB22: 340119 | AD22: TEMA SHOPPING MALL | AE22: 130119 | AG22: TECHIMAN | AH22: 200701 | AJ22: KANTAMANTO | AK22: 240107 | AM22: OSU MEDIUM | AN22: 170125 | AS22: BOUNDARY ROAD | AT22: 40116 | AZ22: RING ROAD BRANCH | BA22: 230119 | BC22: LAW COURT COMPLEX BRANCH | BD22: 50138 | BF22: TARKWA | BG22: 360402 | BI22: OKAISHIE | BJ22: 180121 | BL22: ADJIRIGANO BRANCH | BM22: 110126 | BO22: EAST LEGON BRANCH | BP22: 90122 | BR22: EAST LEGON | BS22: 190119 | BU22: AHODWO | BV22: 20613 | BX22: KUMASI-ADUM | BY22: 60601 | CA22: IFS CAPITAL MANAGEMENT | CB22: 100145 | CD22: CAPE COAST BRANCH | CE22: 120301 | CH22: Absa (GH) LTDAIRPORT CITY | CI22: 30136
A23: Republic Bank (Ghana) Limited | C23: CIRCLE | D23: 30141 | F23: NIMA BRANCH | G23: 280120 | I23: MADINA | J23: 80113 | L23: AGAVE RURAL BANK LTD-DABALE | M23: 70120 | O23: TAMALE | P23: 210801 | X23: PRIVATE BANKING | Y23: 140190 | AA23: ATOMIC JUNCTION BRANCH | AB23: 340120 | AD23: WEIJA | AE23: 130120 | AJ23: TUDU | AK23: 240108 | AM23: TEMA COMM1 | AN23: 170126 | AS23: LIBERTY HOUSE | AT23: 40117 | AZ23: BAATSONA BRANCH | BA23: 230120 | BC23: PARLIAMENT HOUSE BRANCH | BD23: 50139 | BF23: MANHYIA | BG23: 360601 | BI23: EAST LEGON BRANCH | BJ23: 180122 | BL23: COMMUNITY 25 | BM23: 110127 | BO23: AIRPORT CITY BRANCH | BP23: 90123 | BR23: LAPAZ | BS23: 190120 | BU23: HARPER ROAD | BV23: 20615 | BX23: GOLDEN LINK S&L | BY23: 60620 | CA23: ENTERPRISE LIFE ASSURANCE | CB23: 100146 | CD23: TAKORADI MAIN | CE23: 120401 | CH23: Absa (GH) LTDCIRCLE | CI23: 30141
A24: Societe General (Ghana) Limited | C24: ACCRA CORPORATE SERVICE CENTRE | D24: 30144 | F24: TIA BRANCH | G24: 280121 | I24: ABEKALAPAZ | J24: 80114 | L24: MEPE AREA RURAL BANK LTD-MEPE | M24: 70121 | O24: ABII NATIONAL SAVINGS AND LOANS | P24: 210900 | X24: SUAME CIRCUIT CO-OPERATIVE CREDIT U | Y24: 140194 | AA24: DANSOMAN ROUND-ABOUT BRANCH | AB24: 340122 | AD24: ACHIMOTA MILE 7 | AE24: 130121 | AJ24: TEMA-COMMUNITY ONE | AK24: 240109 | AM24: SPINTEX BRANCH 2 | AN24: 170127 | AS24: ACCRA NEW TOWN | AT24: 40118 | AZ24: TEMA MAIN HARBOUR BRANCH | BA24: 230122 | BC24: MADINA BRANCH | BD24: 50146 | BF24: KUMASI CENTRAL MARKET | BG24: 360602 | BI24: BAWALESHIE BRANCH | BJ24: 180123 | BL24: ANT-MIDLAND SAVINGS AND LOANS | BM24: 110128 | BO24: DANSOMAN BRANCH | BP24: 90124 | BR24: STANBIC HEIGHTS | BS24: 190121 | BU24: OBUASI | BV24: 20617 | BX24: TAMALE | BY24: 60801 | CA24: EZI SAVINGS AND LOANS LTD | CB24: 100148 | CD24: TAKORADI HABOUR BRANCH | CE24: 120402 | CH24: Absa (GH) LTDACCRA CORPORATE SERVICE CENTRE | CI24: 30144
A25: Stanbic Bank Ghana Limited | C25: SPINTEX PRESTIGE | D25: 30145 | F25: AIRPORT BRANCH | G25: 280122 | I25: AGONA SWEDRU | J25: 80115 | L25: UNION RURAL BANK LTD-SENYA BREKU | M25: 70122 | O25: ECLIPSE MICROFINANCE | P25: 210910 | X25: JAUBEN RURAL BANK LTD | Y25: 140195 | AA25: DANSOMAN EXHIBITION BRANCH | AB25: 340123 | AD25: MADINA | AE25: 130122 | AJ25: OKAISHIE | AK25: 240110 | AM25: 37 BRANCH | AN25: 170128 | AS25: TRADE FAIR SITE | AT25: 40119 | AZ25: ONE AIRPORT SQUARE | BA25: 230123 | BC25: MAKOLA | BD25: 50147 | BF25: KEJETIA | BG25: 360603 | BI25: NUNGUA BRANCH | BJ25: 180124 | BL25: ANT-ASSURANCE S AND L | BM25: 110129 | BO25: KOFORIDUA | BP25: 90201 | BR25: INTEGRATED PROCESSING CENTER | BS25: 190122 | BU25: TAMALE | BV25: 20823 | BX25: MERCHANT BANK | BY25: 100100 | CA25: PACIFIC SAVINGS AND LOANS LTD | CB25: 100149 | CD25: TARKWA | CE25: 120403 | CH25: Absa (GH) LTDSPINTEX PRESTIGE | CI25: 30145
A26: Standard Chartered Bank (Ghana) Limited | C26: HIGH STREET | D26: 30148 | F26: KASOA BRANCH | G26: 280123 | I26: ADB HOUSE BRANCH | J26: 80116 | L26: ANLO RURAL BANK LTD-ANLOGA | M26: 70123 | O26: GOLDMAN CAPITAL | P26: 210920 | X26: ODOTOBRI RURAL BANK LTD | Y26: 140196 | AA26: RUSSIA ROAD BRANCH | AB26: 340124 | AD26: HAATSOO | AE26: 130123 | AJ26: ACTION CHAPEL | AK26: 240111 | AM26: TRADE FAIR | AN26: 170129 | AS26: KANESHIE INDUSTRIAL AREA | AT26: 40120 | AZ26: DANSOMAN | BA26: 230124 | BC26: ACCRA NEW TOWN | BD26: 50149 | BF26: ANLOGA | BG26: 360604 | BI26: VALLEY VIEW UNIVERSITY BRANCH | BJ26: 180125 | BL26: UG CO-OPERATIVE CREDIT UNION | BM26: 110130 | BO26: AKIM ODA | BP26: 90202 | BR26: CASH CENTRE | BS26: 190123 | CA26: CDH BALANCED FUND | CB26: 100175 | CD26: KUMASI MAIN | CE26: 120601 | CH26: Absa (GH) LTDHIGH STREET | CI26: 30148
A27: United Bank for Africa (Ghana) Limited | C27: DIRECT SALES | D27: 30149 | F27: SPINTEX BRANCH | G27: 280124 | I27: ACHIMOTA | J27: 80117 | L27: ODUPONGKPEHE RURAL BANK LTD-KASOA | M27: 70124 | O27: MIDLAND SAVINGS AND LOANS | P27: 210930 | X27: MIDLAND SAVINGS & LOANS LTD | Y27: 140197 | AA27: DARKUMAN BRANCH | AB27: 340125 | AD27: WESTLANDS | AE27: 130124 | AJ27: A AND C MALL | AK27: 240112 | AM27: FIRST AFRICAN SAVINGS AND LOANS | AN27: 170174 | AS27: ASHAIMAN | AT27: 40121 | AZ27: GLOBAL ACCESS SAVINGS & LOANS CO. LTD | BA27: 230181 | BC27: FIRST GHANA BUILDING SOCIETY-HEAD OFFICE | BD27: 50150 | BF27: KRONUM | BG27: 360605 | BI27: UNIVERSITY OF GHANA BRANCH | BJ27: 180126 | BL27: KOFORIDUA | BM27: 110215 | BO27: CAPE COAST | BP27: 90301 | BR27: WEST HILLS MALL BRANCH | BS27: 190124 | CA27: STALWARD ASSETS COMPANY LIMITED | CB27: 100182 | CD27: ADUM | CE27: 120602 | CH27: Absa (GH) LTDDIRECT SALES | CI27: 30149
A28: Universal Merchant Bank Limited | C28: AVENUE CENTRAL | D28: 30154 | F28: NEWTOWN BRANCH | G28: 280125 | I28: SPINTEX ROAD | J28: 80118 | L28: LA COMMUNITY BANK LTD-LA | M28: 70125 | O28: GHANA HOME LOANS | P28: 210940 | X28: FIRST AFRICAN SAVINGS & LOANS LTD | Y28: 140198 | AA28: DOME BRANCH | AB28: 340126 | AD28: MOTOR WAY ROUNDABOUT | AE28: 130125 | AJ28: DANSOMAN | AK28: 240113 | AM28: UNION SAVINGS AND LOANS LIMITED | AN28: 170175 | AS28: MADINA | AT28: 40123 | AZ28: ASURANCE SAVINGS AND LOANS LTD | BA28: 230184 | BC28: FIRST GHANA BUILDING SOCIETY- ACCRA | BD28: 50151 | BF28: ADUM | BG28: 360606 | BI28: TAIFA BRANCH | BJ28: 180127 | BL28: ASAMANKESE | BM28: 110216 | BO28: DUNKWA | BP28: 90302 | BR28: JUNCTION MALL BRANCH | BS28: 190125 | CA28: GEMINI LIFE INSURANCE COMPANY | CB28: 100183 | CD28: SUAME BRANCH | CE28: 120603 | CH28: Absa (GH) LTDAVENUE CENTRAL | CI28: 30154
A29: Zenith Bank (Ghana) Limited | C29: UNDP | D29: 30155 | F29: HAATSO | G29: 280126 | I29: MAKOLA | J29: 80119 | L29: APEX LINK CENTRE-CEDI HOUSECED HOUSE | M29: 70126 | O29: HIS MAJESTY PHONES | P29: 210950 | X29: OPPORTUNITY SAVINGS & LOANS | Y29: 140199 | AA29: DZORWULU BRANCH | AB29: 340127 | AD29: KOTOBABI | AE29: 130127 | AJ29: RING ROAD | AK29: 240114 | AM29: ENTREPRENUERS CAPITAL CO-OPERATIVE CREDIT UNION | AN29: 170176 | AS29: 31ST DECEMBER MARKET | AT29: 40124 | AZ29: CAPE - COAST BRANCH | BA29: 230301 | BC29: ACHIMOTA BRANCH | BD29: 50152 | BI29: GOLDEN LINK SAVINGS AND LOANS | BJ29: 180199 | BL29: KASOA BRANCH | BM29: 110301 | BO29: TAKORADI | BP29: 90401 | BR29: TUDU BRANCH | BS29: 190127 | CA29: EXPRESS SAVINGS AND LOANS LTD | CB29: 100184 | CD29: SUNYANI | CE29: 120701 | CH29: Absa (GH) LTDUNDP | CI29: 30155
C30: TEMA MAIN | D30: 30160 | F30: AIRPORT | G30: 280127 | I30: ACCRA NEW TOWN | J30: 80120 | L30: ASUOGYAMAN RURAL BANK LTD-ACCRA | M30: 70127 | O30: CIMENTS DE L'AFRIQUE | P30: 210960 | X30: TAKORADI | Y30: 140401 | AA30: EAST LEGON BRANCH | AB30: 340128 | AD30: SAFE BOND | AE30: 130128 | AJ30: HAATSO | AK30: 240115 | AM30: ASI-B SAVINGS AND LOANS | AN30: 170177 | AS30: TETTEH QUARSHIE CIRCLE | AT30: 40126 | AZ30: KASOA BRANCH | BA30: 230302 | BC30: EAST AIRPORT BRANCH | BD30: 50153 | BI30: KOFORIDUA | BJ30: 180201 | BL30: SWEDRU | BM30: 110302 | BO30: SEFWI BEKWAI | BP30: 90402 | BR30: ACHIMOTA MALL BRANCH | BS30: 190128 | CA30: UNIVERSAL PRIVATE BANKING BRANCH | CB30: 100190 | CD30: TAMALE | CE30: 120801 | CH30: Absa (GH) LTDTEMA MAIN | CI30: 30160
C31: SME CENTRE | D31: 30161 | F31: LEGON ACCRA | G31: 280128 | I31: TEMA MERIDIAN | J31: 80121 | L31: CITIZEN RURAL BANK LTD-ACCRA | M31: 70128 | O31: TEMA CHAPTERS TEACHERS NETWORK | P31: 210970 | X31: TARKWA | Y31: 140402 | AA31: GIMPA BRANCH | AB31: 340129 | AD31: LABONE | AE31: 130129 | AJ31: TEMA COMMUNITY 2 | AK31: 240116 | AM31: FAMB -ADOM SAVINGS & LOANS | AN31: 170179 | AS31: KWAME NKRUMAH CIRCLE | AT31: 40127 | AZ31: TAKORADI | BA31: 230401 | BC31: KISSEMAN BRANCH | BD31: 50154 | BI31: CAPECOAST BRANCH | BJ31: 180301 | BL31: CAPE COAST | BM31: 110303 | BO31: SEFWI WIAWSO | BP31: 90403 | BR31: LEGON | BS31: 190130 | CA31: SIC LIFE SAVINGS & LOANS LIMITED | CB31: 100197 | CH31: Absa (GH) LTDSME CENTRE | CI31: 30161
C32: AGBOBLOSHIE | D32: 30162 | F32: ADJIRIGANOR, ACCRA | G32: 280129 | I32: ASHIAMAN | J32: 80124 | L32: OYIBI AREA RURAL BANK LIMITED | M32: 70129 | X32: TAKORADI HARBOUR | Y32: 140403 | AA32: KANESHIE BRANCH | AB32: 340130 | AD32: BURMA CAMP | AE32: 130130 | AJ32: ACCRA CENTRAL POSTBANK | AK32: 240117 | AM32: SIC LIFE SAVINGS AND LOANS LIMITED | AN32: 170180 | AS32: INTERNATIONAL TRADE FINANCE | AT32: 40128 | AZ32: TARKWA | BA32: 230402 | BC32: TESHIE NUNGUA BRANCH | BD32: 50155 | BI32: UNIV. OF CAPE COAST BRANCH | BJ32: 180302 | BL32: WINNEBA | BM32: 110304 | BO32: TARKWA | BP32: 90404 | BR32: ALPHA CAPITAL SAVINGS AND LOANS | BS32: 190131 | CA32: IVORY FINANCE SAVINGS AND LOANS | CB32: 100198 | CH32: Absa (GH) LTDAGBOBLOSHIE | CI32: 30162
C33: MADINA | D33: 30163 | F33: ACCESS -OCTAGON ACCRA | G33: 280130 | I33: DANQUAH CIRCLE | J33: 80125 | L33: MICROFIN RURAL BANK LIMITED | M33: 70130 | X33: ESIAMA BRANCH | Y33: 140404 | AA33: KASOA MAIN BRANCH | AB33: 340131 | AD33: REINSURANCE HOUSE BRANCH | AE33: 130131 | AJ33: ADENTA | AK33: 240118 | AM33: UNICREDIT GHANA LIMITED | AN33: 170181 | AS33: GLOBAL TRANSFER SERVICES | AT33: 40129 | AZ33: AFLAO | BA33: 230501 | BC33: FIRST GHANA BUILDING SOCIETY-TEMA | BD33: 50159 | BI33: TAKORADI HARBOUR | BJ33: 180401 | BL33: TAKORADI | BM33: 110401 | BO33: ESSAM | BP33: 90405 | BR33: SERVICES INTERGRITY SAVINGS AND LOANS LIMITED | BS33: 190132 | CA33: FIRST NATATIONAL S&L | CB33: 100199 | CH33: Absa (GH) LTDMADINA | CI33: 30163
C34: HEAD OFFICE | D34: 30164 | F34: BESTPOINT SAVING & LOANS - ACCRA BANK | G34: 280162 | I34: NIMA | J34: 80126 | L34: GOMOA COMMUNITY BANK | M34: 70131 | X34: SEKONDI ROAD | Y34: 140405 | AA34: KASOA NEW MARKET | AB34: 340132 | AD34: TRUST TOWERS BRANCH | AE34: 130132 | AJ34: IPS | AK34: 240119 | AM34: TADI MARKT CIRCLE | AN34: 170401 | AS34: TANTRA HILL | AT34: 40130 | AZ34: KUMASI-LAKE ROAD | BA34: 230601 | BC34: KOFORIDUA | BD34: 50204 | BI34: TAKORADI MARKET CIRCLE | BJ34: 180402 | BL34: SEFWI WIAWSO | BM34: 110402 | BO34: ASANKRAGUA | BP34: 90406 | BR34: AGJIRINGANOR | BS34: 190133 | CA34: ICGC CHRIST TEMPLE | CB34: 100200 | CH34: Absa (GH) LTDHEAD OFFICE | CI34: 30164
C35: TESHIE NUNGUA | D35: 30168 | F35: FIRST TRUST SAVINGS AND LOANS LTD | G35: 280189 | I35: KASOA | J35: 80127 | L35: APEX BANK KOFORIDUA CENTRE-KOFORIDUA | M35: 70201 | X35: NHYIEASO | Y35: 140601 | AA35: KORLE BU BRANCH | AB35: 340133 | AD35: TESANO BRANCH | AE35: 130133 | AJ35: TRADE FAIR LA | AK35: 240120 | AM35: KUMASI | AN35: 170601 | AS35: KASOA | AT35: 40131 | AZ35: ADUM | BA35: 230602 | BC35: AKIM ODA | BD35: 50218 | BI35: KUMASI | BJ35: 180601 | BL35: SEFWI BEKWAI | BM35: 110403 | BO35: AKONTOMBRA | BP35: 90407 | BR35: TAKORADI | BS35: 190401 | CA35: FIRST INSURANCE CO. LTD | CB35: 100202 | CH35: Absa (GH) LTDTESHIE NUNGUA | CI35: 30168
C36: ACCRA NEWTOWN | D36: 30169 | F36: FASL | G36: 280198 | I36: WINNEBA | J36: 80128 | L36: ASUOPRA RURAL BANK LTD-AFOSU | M36: 70202 | X36: SUAME | Y36: 140602 | AA36: KORLE DUDOR BRANCH | AB36: 340134 | AD36: HOSPITAL ROAD BRANCH | AE36: 130134 | AJ36: TESANO | AK36: 240121 | AM36: SUAME | AN36: 170602 | AS36: DOME (KWABENYA) | AT36: 40132 | AZ36: ALABAR BRANCH | BA36: 230603 | BC36: FIRST GHANA BUILDING SOCIETY- KOFORIDUA | BD36: 50252 | BI36: ADUM-KUMASI | BJ36: 180602 | BL36: JUABESO | BM36: 110404 | BO36: JUABESO | BP36: 90408 | BR36: TARKWA | BS36: 190402 | CA36: BEIGE CAPITAL SAVINGS & LOANS | CB36: 100203 | CH36: Absa (GH) LTDACCRA NEWTOWN | CI36: 30169
C37: DOME | D37: 30170 | F37: KOFORIDUA | G37: 280201 | I37: DIAMOND CEMENT | J37: 80129 | L37: KWAHU RURAL BANK LTD-KWAHU PEPEASE | M37: 70203 | X37: KEJETIA | Y37: 140603 | AA37: KWABENYA BRANCH | AB37: 340135 | AD37: KASOA BRANCH | AE37: 130135 | AJ37: DZORWULU | AK37: 240122 | AM37: MANHYIA | AN37: 170605 | AS37: ABLENKPE | AT37: 40133 | AZ37: KNUST | BA37: 230604 | BC37: CAPE COAST | BD37: 50310 | BI37: AFFUL NKWANTA | BJ37: 180603 | BL37: AKONTOMBRA | BM37: 110405 | BO37: ASEMPANEYE | BP37: 90409 | BR37: HO | BS37: 190501 | CA37: FAMILY CARE FUNERAL TRUST | CB37: 100205 | CH37: Absa (GH) LTDDOME | CI37: 30170
C38: DARKUMAN | D38: 30173 | F38: TARKWA BRANCH | G38: 280401 | I38: KOFORIDUA | J38: 80221 | L38: SOUTH BIRIM RURAL BANK LTD-ACHIASE | M38: 70204 | X38: KNUST | Y38: 140604 | AA38: LABONE BRANCH | AB38: 340136 | AD38: KANTAMANTO BRANCH | AE38: 130136 | AJ38: MAMPROBI POSTBANK | AK38: 240123 | AM38: TAMALE BRANCH | AN38: 170801 | AS38: KASOA MAIN | AT38: 40134 | AZ38: FIRST ALLIED SAVINGS & LOANS LTD | BA38: 230651 | BC38: DUNKWA ON-OFFIN | BD38: 50327 | BI38: ABOABO | BJ38: 180604 | BL38: ESSAM | BM38: 110406 | BO38: ADABOKROM | BP38: 90410 | BR38: HARPER-KUMASI | BS38: 190601 | CA38: COMMERZ SAVINGS AND LOAN | CB38: 100206 | CH38: Absa (GH) LTDDARKUMAN | CI38: 30173
C39: INDEPENDENCE AVENUE | D39: 30175 | F39: TAKORADI BRANCH | G39: 280402 | I39: SUHUM | J39: 80222 | L39: UPPER MANYA KRO RURAL BANK LTD-ASESEWA | M39: 70205 | X39: ASAFO | Y39: 140605 | AA39: LAPAZ BRANCH | AB39: 340137 | AD39: MADINA CENTRAL BRANCH | AE39: 130137 | AJ39: KWAME NKRUMAH AVENUE | AK39: 240124 | AS39: SAFEBOUND (JUBILEE) TEMA | AT39: 40135 | AZ39: ST PETER'S CO-OPERATIVE CREDIT UNION | BA39: 230652 | BC39: SWEDRU BRANCH | BD39: 50337 | BI39: ATONSU | BJ39: 180605 | BL39: ASEMPANAYE | BM39: 110407 | BO39: TAKORADI MARKET CIRCLE | BP39: 90411 | BR39: SUAME | BS39: 190602 | CA39: NDK CAPITAL LIMITED | CB39: 100210 | CH39: Absa (GH) LTDINDEPENDENCE AVENUE | CI39: 30175
C40: WEIJA | D40: 30179 | F40: SEFWI BRANCH | G40: 280403 | I40: NKAWKAW | J40: 80223 | L40: KWAHU PRASO RURAL BANK LTD-KWAHU PRASO | M40: 70206 | X40: TAMALE | Y40: 140801 | AA40: MADINA MAIN BRANCH | AB40: 340138 | AD40: COMMUNITY1 BRANCH | AE40: 130138 | AJ40: ACHIMOTA BRANCH | AK40: 240125 | AS40: KISSEIMAN | AT40: 40136 | AZ40: NOBLE DREAM MICROFINANCE LTD | BA40: 230653 | BC40: KASOA | BD40: 50351 | BI40: SUAME MAAKRO | BJ40: 180606 | BL40: ADABOKROM | BM40: 110408 | BO40: HO | BP40: 90501 | BR40: ADUM | BS40: 190603 | CA40: GHANA STOCK EXCHANGE | CB40: 100211 | CH40: Absa (GH) LTDWEIJA | CI40: 30179
C41: ASHAIMAN | D41: 30184 | F41: ENCHI BRANCH | G41: 280404 | I41: ASIAKWA | J41: 80229 | L41: ATIWA RURAL BANK LTD-KWABENG | M41: 70207 | X41: UEW BRANCH | Y41: 310318 | AA41: MADINA NEW ROAD BRANCH | AB41: 340139 | AD41: SAKUMONO BRANCH | AE41: 130139 | AJ41: GWB LAPAZ | AK41: 240126 | AS41: SPINTEX ROAD | AT41: 40138 | AZ41: ADEHYEMAN SAVINGS & LOANS LTD | BA41: 230680 | BC41: TAKORADI | BD41: 50407 | BI41: SANTASI ROUNDABOUT BRANCH | BJ41: 180607 | BL41: ASANKRAGWA | BM41: 110409 | BO41: ADUM | BP41: 90601 | BR41: ASHTOWN | BS41: 190604 | CA41: DREAMSON GHANA LIMITED | CB41: 100212 | CH41: Absa (GH) LTDASHAIMAN | CI41: 30184
...

Sheet Helper Data
A1: MALE | B1: SINGLE | C1: FULL TIME | D1: YES | E1: SALARY | F1: BANK | G1: MTN | H1: Access Bank (Ghana) Plc | I1: TITLES | J1: WORKER TYPES | K1: Currency | L1: National ID Types | M1: Countries (Nationalities)
A2: FEMALE | B2: MARRIED | C2: PART TIME | D2: NO | E2: WAGE | F2: MOMO | G2: VODAFONE | H2: Agricultural Development Bank Limited | I2: Mr | J2: EMPLOYEE | K2: GHS | L2: Ghana Card | M2: Afghanistan
B3: WIDOWED | C3: CONTRACT | F3: CASH | G3: AIRTELTIGO | H3: Apex Bank GH Limited | I3: Miss | J3: CONTRACTOR | K3: USD | L3: Drivers License | M3: Albania
C4: PROBATION | F4: CHEQUE | H4: Bank of Africa Ghana Limited | I4: Mrs | K4: EUR | L4: NHIS Card | M4: Algeria
H5: Absa (GH) LTD | I5: Ms | K5: GBP | L5: Voters ID Card | M5: American Samoa
H6: CAL Bank Limited | I6: Sir | K6: CNY | L6: Passport | M6: Andorra
H7: Consolidated Bank Ghana Limited | I7: Dr | K7: ZAR | L7: Other | M7: Angola
H8: Ecobank Ghana Limited | I8: Chancellor | M8: Anguilla
H9: FBNBank (Ghana) Limited | I9: Vice-Chancellor | M9: Antigua & Barbuda
H10: Fidelity Bank Limited | I10: Excellency | M10: Argentina
H11: First Atlantic Bank Limited | I11: Professor | M11: Armenia
H12: First National Bank (Ghana) Limited | M12: Aruba
H13: GCB Bank Limited | M13: Australia
H14: GHL Bank Limited | M14: Austria
H15: Guaranty Trust Bank (Ghana) Limited | M15: Azerbaijan
H16: National Investment Bank Limited | M16: Bahamas, The
H17: Omni-BSIC Bank Ghana Limited | M17: Bahrain
H18: Prudential Bank Limited | M18: Bangladesh
H19: Republic Bank (Ghana) Limited | M19: Barbados
H20: Societe General (Ghana) Limited | M20: Belarus
H21: Stanbic Bank Ghana Limited | M21: Belgium
H22: Standard Chartered Bank (Ghana) Limited | M22: Belize
H23: United Bank for Africa (Ghana) Limited | M23: Benin
... H26: Other | M26: Bolivia
M27: Bosnia & Herzegovina
M28: Botswana
M29: Brazil
M30: British Virgin Is.
M31: Brunei
M32: Bulgaria
M33: Burkina Faso
M34: Burma
M35: Burundi
M36: Cambodia
M37: Cameroon
M38: Canada
... M228: Zimbabwe
